<?xml version="1.0" ?>
<sdf version="1.8">
  <model name="myrobot">
    <pose>0 0 0 0 0 0</pose>

    <link name="base_footprint"/>

    <link name="base_link">
        <pose>0.5 0 0.1 0 0 0</pose>
        
        <visual name="base_visual">
            <pose>0 0 0 0 0 0</pose>
            <geometry>
                <box>
                    <size>1.2 0.6 0.2</size>
                </box>
            </geometry>
            <material>
                <ambient>0.5 0.5 0.5 1</ambient>
                <diffuse>0.5 0.5 0.5 1</diffuse>
            </material>
        </visual>

        <collision name="base_collision">
            <pose>0 0 0 0 0 0</pose>
            <geometry>
                <box>
                    <size>1 0.6 0.2</size>
                </box>
            </geometry>
        </collision>

        <inertial>
            <pose>0 0 0 0 0 0</pose>
            <mass>10</mass>
            <inertia>
                <ixx>0.1</ixx>
                <iyy>0.1</iyy>
                <izz>0.1</izz>
                <ixy>0</ixy>
                <ixz>0</ixz>
                <iyz>0</iyz>
            </inertia>
        </inertial>
    </link>

    <link name="lbwheel">
        <pose>0.5 0.4 0.1 -1.57 0 0</pose>

         <visual name="lbwheel_visual">
            <pose>0 0 0 0 0 0</pose>
            <geometry>
                <cylinder>
                    <radius>0.2</radius>
                    <length>0.2</length>
                </cylinder>
            </geometry>
            <material>
                <ambient>0 0 0 1</ambient>
                <diffuse>0 0 0 1</diffuse>
            </material>
        </visual>

        <collision name="lbwheel_collision">
            <pose>0 0 0 0 0 0</pose>
            <geometry>
                <cylinder>
                    <radius>0.2</radius>
                    <length>0.2</length>
                </cylinder>
            </geometry>
            <surface>
            <friction>
            <ode>
              <mu>100</mu>
              <mu2>100</mu2>
            </ode>
            </friction>
            <contact>
            <ode>
              <soft_cfm>0</soft_cfm>
              <soft_erp>0.2</soft_erp>
              <kp>1e+5</kp>
              <kd>1</kd>
              <max_vel>0.01</max_vel>
              <min_depth>0.001</min_depth>
            </ode>
          </contact>
          </surface>
        </collision>

        <inertial>
            <pose>0 0 0 0 0 0</pose>
            <mass>2</mass>
            <inertia>
                <ixx>0.01</ixx>
                <iyy>0.01</iyy>
                <izz>0.01</izz>
                <ixy>0</ixy>
                <ixz>0</ixz>
                <iyz>0</iyz>
            </inertia>
        </inertial>
    </link>

    <link name="rbwheel">
        <pose>0.1 0 0.1 0 0 0</pose>

         <visual name="rbwheel_visual">
            <pose>0 0 0 0 0 0</pose>
            <geometry>
                <sphere>
                    <radius>0.2</radius>
                </sphere>
            </geometry>
            <material>
                <ambient>0 0 0 1</ambient>
                <diffuse>0 0 0 1</diffuse>
            </material>
        </visual>

        <collision name="rbwheel_collision">
            <pose>0 0 0 0 0 0</pose>
            <geometry>
                <sphere>
                    <radius>0.2</radius>
                </sphere>
            </geometry>
            <surface>
            <friction>
            <ode>
              <mu>0.01</mu>
              <mu2>0.01</mu2>
            </ode>
            </friction>
          <contact>
            <ode>
              <soft_cfm>0</soft_cfm>
              <soft_erp>0.2</soft_erp>
            </ode>
          </contact>
        </surface>
        </collision>

        <inertial>
            <pose>0 0 0 0 0 0</pose>
            <mass>0.5</mass>
            <inertia>
                <ixx>0.00001</ixx>
                <iyy>0.00001</iyy>
                <izz>0.00001</izz>
                <ixy>0</ixy>
                <ixz>0</ixz>
                <iyz>0</iyz>
            </inertia>
        </inertial>
    </link>

    <link name="rfwheel">
        <pose>0.5 -0.4 0.1 -1.57 0 0</pose>

         <visual name="rfwheel_visual">
            <pose>0 0 0 0 0 0</pose>
            <geometry>
                <cylinder>
                    <radius>0.2</radius>
                    <length>0.2</length>
                </cylinder>
            </geometry>
            <material>
                <ambient>0 0 0 1</ambient>
                <diffuse>0 0 0 1</diffuse>
            </material>
        </visual>

        <collision name="rfwheel_collision">
            <pose>0 0 0 0 0 0</pose>
            <geometry>
                <cylinder>
                    <radius>0.2</radius>
                    <length>0.2</length>
                </cylinder>
            </geometry>
            <surface>
            <friction>
            <ode>
              <mu>100</mu>
              <mu2>100</mu2>
            </ode>
            </friction>
            <contact>
            <ode>
              <soft_cfm>0</soft_cfm>
              <soft_erp>0.2</soft_erp>
              <kp>1e+5</kp>
              <kd>1</kd>
              <max_vel>0.01</max_vel>
              <min_depth>0.001</min_depth>
            </ode>
          </contact>
          </surface>
        </collision>

        <inertial>
            <pose>0 0 0 0 0 0</pose>
            <mass>2</mass>
            <inertia>
                <ixx>0.01</ixx>
                <iyy>0.01</iyy>
                <izz>0.01</izz>
                <ixy>0</ixy>
                <ixz>0</ixz>
                <iyz>0</iyz>
            </inertia>
        </inertial>
    </link>

    <link name="lfwheel">
        <pose>0.9 0 0.1 0 0 0</pose>

         <visual name="lfwheel_visual">
            <pose>0 0 0 0 0 0</pose>
            <geometry>
                <sphere>
                    <radius>0.2</radius>
                </sphere>
            </geometry>
            <material>
                <ambient>0 0 0 1</ambient>
                <diffuse>0 0 0 1</diffuse>
            </material>
        </visual>

        <collision name="lfwheel_collision">
            <pose>0 0 0 0 0 0</pose>
            <geometry>
                <sphere>
                    <radius>0.2</radius>
                </sphere>
            </geometry>
            <surface>
            <friction>
            <ode>
              <mu>0.01</mu>
              <mu2>0.01</mu2>
            </ode>
            </friction>
          <contact>
            <ode>
              <soft_cfm>0</soft_cfm>
              <soft_erp>0.2</soft_erp>
            </ode>
          </contact>
        </surface>
        </collision>

        <inertial>
            <pose>0 0 0 0 0 0</pose>
            <mass>0.5</mass>
            <inertia>
                <ixx>0.00001</ixx>
                <iyy>0.00001</iyy>
                <izz>0.00001</izz>
                <ixy>0</ixy>
                <ixz>0</ixz>
                <iyz>0</iyz>
            </inertia>
        </inertial>
    </link>

    <link name="shooter_base">
        <pose>0.5 0 0.25 0 0 0</pose>

         <visual name="shooter_base_visual">
            <pose>0 0 0 0 0 0</pose>
            <geometry>
                <cylinder>
                    <radius>0.18</radius>
                    <length>0.1</length>
                </cylinder>
            </geometry>
            <material>
                <ambient>0.1 0.4 0.1 1</ambient>
                <diffuse>0.1 0.4 0.1 1</diffuse>
            </material>
        </visual>

        <collision name="shooter_base_collision">
            <pose>0 0 0 0 0 0</pose>
            <geometry>
                <cylinder>
                    <radius>0.18</radius>
                    <length>0.2</length>
                </cylinder>
            </geometry>
        </collision>

        <inertial>
            <pose>0 0 0 0 0 0</pose>
            <mass>1</mass>
            <inertia>
                <ixx>0.01</ixx>
                <iyy>0.01</iyy>
                <izz>0.01</izz>
                <ixy>0</ixy>
                <ixz>0</ixz>
                <iyz>0</iyz>
            </inertia>
        </inertial>
    </link>

    <link name="rotator">
        <pose>0.5 0 0.315 0 0 0</pose>

         <visual name="rotator_visual">
            <pose>0 0 0 0 0 0</pose>
            <geometry>
                <cylinder>
                    <radius>0.17</radius>
                    <length>0.03</length>
                </cylinder>
            </geometry>
            <material> 
                <ambient>0.2 0.2 0.2 1</ambient>
                <diffuse>0.2 0.2 0.2 1</diffuse>
            </material>
        </visual>

        <collision name="rotator_collision">
            <pose>0 0 0 0 0 0</pose>
            <geometry>
                <cylinder>
                    <radius>0.17</radius>
                    <length>0.03</length>
                </cylinder>
            </geometry>
        </collision>

        <inertial>
            <pose>0 0 0 0 0 0</pose>
            <mass>0.05</mass>
            <inertia>
                <ixx>0.001</ixx>
                <iyy>0.001</iyy>
                <izz>0.001</izz>
                <ixy>0</ixy>
                <ixz>0</ixz>
                <iyz>0</iyz>
            </inertia>
        </inertial>
    </link>





  <!-- joints-->

  <joint name="base_joint" type="fixed">
    <parent>base_footprint</parent>
    <child>base_link</child>
  </joint>

  <joint name="lbwheel_joint" type="revolute">
    <parent>base_link</parent>
    <child>lbwheel</child>
    <axis>
      <xyz>0 0 1</xyz>
        <limit>
          <effort>20</effort>
        </limit>
    </axis>
  </joint>

  <joint name="rfwheel_joint" type="revolute">
    <parent>base_link</parent>
    <child>rfwheel</child>
    <axis>
      <xyz>0 0 1</xyz>
        <limit>
          <effort>20</effort>
        </limit>
    </axis>
  </joint>
  
  <joint name="rbwheel_joint" type="ball">
    <parent>base_link</parent>
    <child>rbwheel</child>
  </joint>

  <joint name="lfwheel_joint" type="ball">
    <parent>base_link</parent>
    <child>lfwheel</child>
  </joint>
  
  <joint name="shooter_base_joint" type="fixed">
    <parent>base_link</parent>
    <child>shooter_base</child>
  </joint>

  <joint name="rotator_joint" type="revolute">
    <parent>shooter_base</parent>
    <child>rotator</child>
    <axis>
      <xyz>0 0 1</xyz>
      <limit>
        <lower>-3.14</lower>
        <upper>3.14</upper>
        <effort>1000</effort>
        <velocity>2.5</velocity>
      </limit>
        <dynamics>
            <damping>0.2</damping> <!-- Added damping to reduce wobbling -->
        </dynamics>
    </axis>
  </joint>

 <!-- Plugins -->

    <plugin filename="gz-sim-joint-state-publisher-system" name="gz::sim::systems::JointStatePublisher">
      <topic>joint_states</topic>
    </plugin>


    <!-- Joint position controller for the rotator -->
    <plugin filename="gz-sim-joint-position-controller-system" name="gz::sim::systems::JointPositionController">
      <joint_name>rotator_joint</joint_name>
      <topic>rotate_joint_position_controller/command</topic>
      <initial_position>0</initial_position>
        <pid>
            <p>1000</p>
            <i>50</i>
            <d>10</d>
        </pid>
    </plugin>

    <!-- Differential drive which controls the back 2 wheels and the front ones act as castor wheels -->
    <plugin filename="gz-sim-diff-drive-system" name="gz::sim::systems::DiffDrive">
      <left_joint>lbwheel_joint</left_joint>
      <right_joint>rbwheel_joint</right_joint>
    <wheel_separation>0.8</wheel_separation>
      <wheel_radius>0.2</wheel_radius>
      <max_linear_acceleration>2.0</max_linear_acceleration>
      <topic>cmd_vel</topic>
      <odom_topic>odom</odom_topic>
      <frame_id>odom</frame_id>
      <child_frame_id>base_footprint</child_frame_id>
      <odom_publisher_frequency>30</odom_publisher_frequency>
      <tf_topic>/tf</tf_topic>
    </plugin>

  </model>
</sdf>
