<?xml version="1.0" ?>
<sdf version="1.8">
  <model name="myrobot">
    <pose>0 0 0 0 0 0</pose>

    <link name="base_footprint"/>

    <link name="base_link">
        <pose>0.5 0 0.1 0 0 0</pose>
        
        <visual name="base_visual">
            <pose>0 0 0 0 0 0</pose>
            <geometry>
                <box>
                    <size>1.1 0.6 0.2</size>
                </box>
            </geometry>
            <material>
                <ambient>0.5 0.5 0.5 1</ambient>
                <diffuse>0.5 0.5 0.5 1</diffuse>
            </material>
        </visual>

        <collision name="base_collision">
            <pose>0 0 0 0 0 0</pose>
            <geometry>
                <box>
                    <size>1.1 0.6 0.2</size>
                </box>
            </geometry>
        </collision>

        <inertial>
            <pose>0 0 0 0 0 0</pose>
            <mass>10</mass>
            <inertia>
                <ixx>0.1</ixx>
                <iyy>0.1</iyy>
                <izz>0.1</izz>
                <ixy>0</ixy>
                <ixz>0</ixz>
                <iyz>0</iyz>
            </inertia>
        </inertial>
    </link>

    <link name="lbwheel">
        <pose>0.1 0.4 0.1 -1.57 0 0</pose>

         <visual name="lbwheel_visual">
            <pose>0 0 0 0 0 0</pose>
            <geometry>
                <cylinder>
                    <radius>0.2</radius>
                    <length>0.2</length>
                </cylinder>
            </geometry>
            <material>
                <ambient>0 0 0 1</ambient>
                <diffuse>0 0 0 1</diffuse>
            </material>
        </visual>

        <collision name="lbwheel_collision">
            <pose>0 0 0 0 0 0</pose>
            <geometry>
                <cylinder>
                    <radius>0.2</radius>
                    <length>0.2</length>
                </cylinder>
            </geometry>
            <surface>
            <friction>
            <ode>
              <mu>100</mu>
              <mu2>100</mu2>
            </ode>
            </friction>
            <contact>
            <ode>
              <soft_cfm>0</soft_cfm>
              <soft_erp>0.2</soft_erp>
              <kp>1e+5</kp>
              <kd>1</kd>
              <max_vel>0.01</max_vel>
              <min_depth>0.001</min_depth>
            </ode>
          </contact>
          </surface>
        </collision>

        <inertial>
            <pose>0 0 0 0 0 0</pose>
            <mass>2</mass>
            <inertia>
                <ixx>0.01</ixx>
                <iyy>0.01</iyy>
                <izz>0.01</izz>
                <ixy>0</ixy>
                <ixz>0</ixz>
                <iyz>0</iyz>
            </inertia>
        </inertial>
    </link>
    <link name="rbwheel">
        <pose>0.1 -0.4 0.1 -1.57 0 0</pose>

         <visual name="rbwheel_visual">
            <pose>0 0 0 0 0 0</pose>
            <geometry>
                <cylinder>
                    <radius>0.2</radius>
                    <length>0.2</length>
                </cylinder>
            </geometry>
            <material>
                <ambient>0 0 0 1</ambient>
                <diffuse>0 0 0 1</diffuse>
            </material>
        </visual>

        <collision name="rbwheel_collision">
            <pose>0 0 0 0 0 0</pose>
            <geometry>
                <cylinder>
                    <radius>0.2</radius>
                    <length>0.2</length>
                </cylinder>
            </geometry>
            <surface>
            <friction>
            <ode>
              <mu>100</mu>
              <mu2>100</mu2>
            </ode>
            </friction>
            <contact>
            <ode>
              <soft_cfm>0</soft_cfm>
              <soft_erp>0.2</soft_erp>
              <kp>1e+5</kp>
              <kd>1</kd>
              <max_vel>0.01</max_vel>
              <min_depth>0.001</min_depth>
            </ode>
          </contact>
          </surface>
        </collision>

        <inertial>
            <pose>0 0 0 0 0 0</pose>
            <mass>2</mass>
            <inertia>
                <ixx>0.01</ixx>
                <iyy>0.01</iyy>
                <izz>0.01</izz>
                <ixy>0</ixy>
                <ixz>0</ixz>
                <iyz>0</iyz>
            </inertia>
        </inertial>
    </link>

    <link name="fcastorwheel">
        <pose>0.9 0 0.1 0 0 0</pose>

         <visual name="fcastorwheel_visual">
            <pose>0 0 0 0 0 0</pose>
            <geometry>
                <sphere>
                    <radius>0.2</radius>
                </sphere>
            </geometry>
            <material>
                <ambient>0 0 0 1</ambient>
                <diffuse>0 0 0 1</diffuse>
            </material>
        </visual>

        <collision name="fcastorwheel_collision">
            <pose>0 0 0 0 0 0</pose>
            <geometry>
                <sphere>
                    <radius>0.2</radius>
                </sphere>
            </geometry>
            <surface>
            <friction>
            <ode>
              <mu>0.01</mu>
              <mu2>0.01</mu2>
            </ode>
            </friction>
          <contact>
            <ode>
              <soft_cfm>0</soft_cfm>
              <soft_erp>0.2</soft_erp>
            </ode>
          </contact>
        </surface>
        </collision>

        <inertial>
            <pose>0 0 0 0 0 0</pose>
            <mass>0.5</mass>
            <inertia>
                <ixx>0.00001</ixx>
                <iyy>0.00001</iyy>
                <izz>0.00001</izz>
                <ixy>0</ixy>
                <ixz>0</ixz>
                <iyz>0</iyz>
            </inertia>
        </inertial>
    </link>

    <link name="shooter_base">
        <pose>0.5 0 0.25 0 0 0</pose>

         <visual name="shooter_base_visual">
            <pose>0 0 0 0 0 0</pose>
            <geometry>
                <cylinder>
                    <radius>0.18</radius>
                    <length>0.1</length>
                </cylinder>
            </geometry>
            <material>
                <ambient>0.1 0.4 0.1 1</ambient>
                <diffuse>0.1 0.4 0.1 1</diffuse>
            </material>
        </visual>

        <collision name="shooter_base_collision">
            <pose>0 0 0 0 0 0</pose>
            <geometry>
                <cylinder>
                    <radius>0.18</radius>
                    <length>0.2</length>
                </cylinder>
            </geometry>
        </collision>

        <inertial>
            <pose>0 0 0 0 0 0</pose>
            <mass>1</mass>
            <inertia>
                <ixx>0.01</ixx>
                <iyy>0.01</iyy>
                <izz>0.01</izz>
                <ixy>0</ixy>
                <ixz>0</ixz>
                <iyz>0</iyz>
            </inertia>
        </inertial>
    </link>

    <link name="rotator">
        <pose>0.5 0 0.315 0 0 0</pose>

         <visual name="rotator_visual">
            <pose>0 0 0 0 0 0</pose>
            <geometry>
                <cylinder>
                    <radius>0.17</radius>
                    <length>0.03</length>
                </cylinder>
            </geometry>
            <material> 
                <ambient>0.2 0.2 0.2 1</ambient>
                <diffuse>0.2 0.2 0.2 1</diffuse>
            </material>
        </visual>

        <collision name="rotator_collision">
            <pose>0 0 0 0 0 0</pose>
            <geometry>
                <cylinder>
                    <radius>0.17</radius>
                    <length>0.03</length>
                </cylinder>
            </geometry>
        </collision>

        <inertial>
            <pose>0 0 0 0 0 0</pose>
            <mass>0.05</mass>
            <inertia>
                <ixx>0.001</ixx>
                <iyy>0.001</iyy>
                <izz>0.001</izz>
                <ixy>0</ixy>
                <ixz>0</ixz>
                <iyz>0</iyz>
            </inertia>
        </inertial>
    </link>

    <link name="barrel">
        <pose>0.5 0 0.355 0 0 0</pose>

         <visual name="barrel_visual">
            <pose>0 0 0 0 0 0</pose>
            <geometry>
                <mesh>
                    <uri>model://shooter/meshes/barrel.stl</uri>
                    <scale>1 1 1</scale>
                </mesh>
            </geometry>
            <material>
                <ambient>0 0 0 1</ambient>
                <diffuse>0 0 0 1</diffuse>
            </material>
        </visual>

        <collision name="barrel_collision">
            <pose>0 0 0 0 0 0</pose>
            <geometry>
                <mesh>
                    <uri>model://shooter/meshes/barrel.stl</uri>
                    <scale>1 1 1</scale>
                </mesh>
            </geometry>
        </collision>

        <inertial>
            <pose>0 0 0 0 0 0</pose>
            <mass>20</mass> <!-- Increased mass -->
            <inertia>
                <ixx>0.005</ixx> <!-- Increased inertia -->
                <iyy>0.005</iyy>
                <izz>0.005</izz>
                <ixy>0</ixy>
                <ixz>0</ixz>
                <iyz>0</iyz>
            </inertia>
        </inertial>
    </link>

    <link name="connector">
        <pose>0.5 0 0.355 0 0 0</pose>

         <visual name="connector_visual">
            <pose>0 0 0 0 0 0</pose>
            <geometry>
                <sphere>
                    <radius>0.045</radius>
                </sphere>
            </geometry>
            <material> 
                <ambient>0.1 0.1 0.5 1</ambient>
                <diffuse>0.1 0.1 0.5 1</diffuse>
            </material>
        </visual>

        <collision name="connector_collision">
            <pose>0 0 0 0 0 0</pose>
            <geometry>
                <sphere>
                    <radius>0.045</radius>
                </sphere>
            </geometry>
        </collision>

        <inertial>
            <pose>0 0 0 0 0 0</pose>
            <mass>0.1</mass>
            <inertia>
                <ixx>1e-5</ixx>
                <iyy>1e-5</iyy>
                <izz>1e-5</izz>
                <ixy>0</ixy>
                <ixz>0</ixz>
                <iyz>0</iyz>
            </inertia>
        </inertial>
    </link>

    <link name="stopper">
        <pose>0.58 0 0.355 0 1.57 0</pose>

         <visual name="stopper_visual">
            <pose>0 0 0 0 0 0</pose>
            <geometry>
                <cylinder>
                    <radius>0.0165</radius>
                    <length>0.05</length>
                </cylinder>
            </geometry>
            <material>
                <ambient>0.5 0.5 0.5 1</ambient>
                <diffuse>0.5 0.5 0.5 1</diffuse>
            </material>
        </visual>

        <collision name="stopper_collision">
            <pose>0 0 0 0 0 0</pose>
            <geometry>
                <cylinder>
                    <radius>0.0165</radius>
                    <length>0.05</length>
                </cylinder>
            </geometry>
        </collision>

        <inertial>
            <pose>0 0 0 0 0 0</pose>
            <mass>0.001</mass> <!-- Increased mass -->
            <inertia>
                <ixx>0.0005</ixx> <!-- Increased inertia -->
                <iyy>0.0005</iyy>
                <izz>0.0005</izz>
                <ixy>0</ixy>
                <ixz>0</ixz>
                <iyz>0</iyz>
            </inertia>
        </inertial>
    </link>

    <!-- Camera -->
    <link name="camera">
      <pose>1.1 0 0.2 0 0 0</pose>
      <inertial>
        <mass>0.1</mass>
        <inertia>
          <ixx>0.001</ixx>
          <ixy>0.0</ixy>
          <ixz>0.0</ixz>
          <iyy>0.001</iyy>
          <iyz>0.0</iyz>
          <izz>0.001</izz>
        </inertia>
      </inertial>
      <visual name="camera_visual">
        <pose>0 0 0 0 0 0</pose>
        <geometry>
          <box>
            <size>0.05 0.08 0.06</size>
          </box>
        </geometry>
        <material> <!-- black colour for camera-->
          <ambient>0 0 0 1</ambient>
          <diffuse>0 0 0 1</diffuse>
        </material>
      </visual>
      <sensor name="camera_sensor" type="camera">
        <pose>0.025 0 0 0 0 0</pose>
        <camera>
          <horizontal_fov>1.047</horizontal_fov>
          <image>
            <width>640</width>
            <height>480</height>
            <format>R8G8B8</format>
          </image>
          <clip>
            <near>0.1</near>
            <far>100</far>
          </clip>
        </camera>
        <always_on>1</always_on>
        <update_rate>30</update_rate>
        <visualize>true</visualize>
        <topic>camera/image_raw</topic>
      </sensor>
    </link>

    <!-- Camera RGB Optical Frame -->
    <link name="camera_rgb_optical_frame">
      <pose>1.125 0 0.1 0 0 0</pose>
      <inertial>
        <mass>0.001</mass>
        <inertia>
          <ixx>0.0001</ixx>
          <ixy>0.0</ixy>
          <ixz>0.0</ixz>
          <iyy>0.0001</iyy>
          <iyz>0.0</iyz>
          <izz>0.0001</izz>
        </inertia>
      </inertial>
    </link>

  <!-- joints-->

  <joint name="base_joint" type="fixed">
    <parent>base_footprint</parent>
    <child>base_link</child>
  </joint>

  <joint name="lbwheel_joint" type="revolute">
    <parent>base_link</parent>
    <child>lbwheel</child>
    <axis>
      <xyz>0 0 1</xyz>
        <limit>
          <effort>20</effort>
        </limit>
    </axis>
  </joint>

  <joint name="rbwheel_joint" type="revolute">
    <parent>base_link</parent>
    <child>rbwheel</child>
    <axis>
      <xyz>0 0 1</xyz>
        <limit>
          <effort>20</effort>
        </limit>
    </axis>
  </joint>

  <joint name="fcastorwheel_joint" type="ball">
    <parent>base_link</parent>
    <child>fcastorwheel</child>
  </joint>
  
  <joint name="shooter_base_joint" type="fixed">
    <parent>base_link</parent>
    <child>shooter_base</child>
  </joint>

  <joint name="rotator_joint" type="revolute">
    <parent>shooter_base</parent>
    <child>rotator</child>
    <axis>
      <xyz>0 0 1</xyz>
      <limit>
        <lower>-3.14</lower>
        <upper>3.14</upper>
        <effort>1000</effort>
        <velocity>2.5</velocity>
      </limit>
        <dynamics>
            <damping>0.2</damping> <!-- Added damping to reduce wobbling -->
        </dynamics>
    </axis>
  </joint>

  <joint name="barrel_joint" type="revolute">
    <parent>rotator</parent>
    <child>barrel</child>
    <axis>
      <xyz>0 -1 0</xyz>
      <limit>
        <lower>0</lower>
        <upper>1.57</upper>
        <effort>100</effort> <!-- Increased effort 10 times -->
        <velocity>100</velocity>
      </limit>
      <dynamics>
        <damping>0.2</damping> <!-- Added damping to reduce wobbling -->
      </dynamics>
    </axis>
  </joint>

  <joint name="connector_joint" type="fixed">
    <parent>barrel</parent>
    <child>connector</child>
  </joint>  

  <joint name="stopper_joint" type="prismatic">
    <parent>barrel</parent>
    <child>stopper</child>
    <axis>
      <xyz>0 0 1</xyz>
      <limit>
        <lower>0</lower>
        <upper>0.95</upper>
        <effort>1000</effort> <!-- Increased effort 10 times -->
        <velocity>10000</velocity> <!-- Corrected velocity limit to allow movement -->
      </limit>
      <dynamics>
        <damping>0.001</damping> <!-- Added damping to reduce wobbling -->
      </dynamics>
    </axis>
  </joint>

  <joint name="camera_joint" type="fixed">
    <parent>base_link</parent>
    <child>camera</child>
  </joint>

  <joint name="camera_rgb_joint" type="fixed">
    <parent>camera</parent>
    <child>camera_rgb_optical_frame</child>
    <pose>0.025 0 0 -1.5708 0 -1.5708</pose>
  </joint>

  <!-- Plugins -->

    <plugin filename="gz-sim-joint-state-publisher-system" name="gz::sim::systems::JointStatePublisher">
      <topic>joint_states</topic>
    </plugin>


    <!-- Joint position controller for the rotator -->
    <plugin filename="gz-sim-joint-position-controller-system" name="gz::sim::systems::JointPositionController">
      <joint_name>rotator_joint</joint_name>
      <topic>rotate_joint_position_controller/command</topic>
      <initial_position>0</initial_position>
        <pid>
            <p>1000</p>
            <i>50</i>
            <d>10</d>
        </pid>
    </plugin>

    <!-- Joint position controller for the barrel -->
    <plugin filename="gz-sim-joint-position-controller-system" name="gz::sim::systems::JointPositionController">
      <joint_name>barrel_joint</joint_name>
      <topic>barrel_joint_position_controller/command</topic>
      <initial_position>0</initial_position>
    <pid>
        <p>1500</p> <!-- Increased proportional gain -->
        <i>100</i> <!-- Increased integral gain -->
        <d>20</d> <!-- Increased derivative gain -->
    </pid>
    </plugin>

    <!-- Joint position controller for the stopper -->
    <plugin filename="gz-sim-joint-position-controller-system" name="gz::sim::systems::JointPositionController">
      <joint_name>stopper_joint</joint_name>
      <topic>stopper_joint_position_controller/command</topic>
      <initial_position>0</initial_position>
    <pid>
        <p>3000</p> <!-- Increased proportional gain -->
        <i>200</i> <!-- Increased integral gain -->
        <d>50</d> <!-- Increased derivative gain -->
    </pid>
    </plugin>

    <!-- Differential drive which controls the back 2 wheels and the front ones act as castor wheels -->
    <plugin filename="gz-sim-diff-drive-system" name="gz::sim::systems::DiffDrive">
      <left_joint>lbwheel_joint</left_joint>
      <right_joint>rbwheel_joint</right_joint>
    <wheel_separation>0.8</wheel_separation>
      <wheel_radius>0.2</wheel_radius>
      <max_linear_acceleration>2.0</max_linear_acceleration>
      <topic>cmd_vel</topic>
      <odom_topic>odom</odom_topic>
      <frame_id>odom</frame_id>
      <child_frame_id>base_footprint</child_frame_id>
      <odom_publisher_frequency>30</odom_publisher_frequency>
      <tf_topic>/tf</tf_topic>
    </plugin>

    <!-- Camera sensor plugin -->
    <plugin filename="gz-sim-sensors-system" name="gz::sim::systems::Sensors">
      <render_engine>ogre2</render_engine>
    </plugin>


  </model>
</sdf>
