<?xml version="1.0" ?>
<robot name="turtlebot3_waffle_pi" xmlns:xacro="http://www.ros.org/wiki/xacro">

  <!-- Include common properties -->
  <xacro:include filename="$(find turtlebot3_description)/urdf/common_properties.urdf"/>

  <!-- Base footprint -->
  <link name="base_footprint"/>

  <!-- Base link -->
  <joint name="base_joint" type="fixed">
    <parent link="base_footprint"/>
    <child link="base_link" />
    <origin xyz="0 0 0.010" rpy="0 0 0"/>
  </joint>

  <link name="base_link">
    <visual>
      <origin xyz="-0.064 0 0.048" rpy="0 0 0"/>
      <geometry>
        <mesh filename="package://turtlebot3_description/meshes/bases/waffle_pi_base.stl" scale="0.001 0.001 0.001"/>
      </geometry>
      <material name="light_black"/>
    </visual>
    <collision>
      <origin xyz="-0.064 0 0.047" rpy="0 0 0"/>
      <geometry>
        <box size="0.266 0.266 0.094"/>
      </geometry>
    </collision>
    <inertial>
      <origin xyz="0 0 0" rpy="0 0 0"/>
      <mass value="1.3729096e+00"/>
      <inertia ixx="8.7002718e-03" ixy="-4.7576583e-05" ixz="1.1160499e-04"
               iyy="8.6195418e-03" iyz="-3.5422299e-06"
               izz="1.4612727e-02" />
    </inertial>
  </link>

  <!-- Wheels -->
  <joint name="wheel_left_joint" type="continuous">
    <parent link="base_link"/>
    <child link="wheel_left_link"/>
    <origin xyz="0.0 0.144 0.023" rpy="-1.57 0 0"/>
    <axis xyz="0 0 1"/>
  </joint>

  <link name="wheel_left_link">
    <visual>
      <origin xyz="0 0 0" rpy="1.57 0 0"/>
      <geometry>
        <mesh filename="package://turtlebot3_description/meshes/wheels/left_tire.stl" scale="0.001 0.001 0.001"/>
      </geometry>
      <material name="dark"/>
    </visual>
    <collision>
      <origin xyz="0 0 0" rpy="0 0 0"/>
      <geometry>
        <cylinder length="0.018" radius="0.033"/>
      </geometry>
    </collision>
    <inertial>
      <origin xyz="0 0 0" />
      <mass value="2.8498940e-02" />
      <inertia ixx="1.1175580e-05" ixy="-4.2369783e-11" ixz="-5.9381719e-09"
               iyy="1.1192413e-05" iyz="-1.4400107e-11" izz="2.0712558e-05" />
    </inertial>
  </link>

  <joint name="wheel_right_joint" type="continuous">
    <parent link="base_link"/>
    <child link="wheel_right_link"/>
    <origin xyz="0.0 -0.144 0.023" rpy="-1.57 0 0"/>
    <axis xyz="0 0 1"/>
  </joint>

  <link name="wheel_right_link">
    <visual>
      <origin xyz="0 0 0" rpy="1.57 0 0"/>
      <geometry>
        <mesh filename="package://turtlebot3_description/meshes/wheels/right_tire.stl" scale="0.001 0.001 0.001"/>
      </geometry>
      <material name="dark"/>
    </visual>
    <collision>
      <origin xyz="0 0 0" rpy="0 0 0"/>
      <geometry>
        <cylinder length="0.018" radius="0.033"/>
      </geometry>
    </collision>
    <inertial>
      <origin xyz="0 0 0" />
      <mass value="2.8498940e-02" />
      <inertia ixx="1.1175580e-05" ixy="-4.2369783e-11" ixz="-5.9381719e-09"
               iyy="1.1192413e-05" iyz="-1.4400107e-11" izz="2.0712558e-05" />
    </inertial>
  </link>

  <!-- LiDAR -->
  <joint name="lidar_joint" type="fixed">
    <parent link="base_link"/>
    <child link="base_scan"/>
    <origin xyz="-0.064 0 0.121" rpy="0 0 0"/>
  </joint>

  <link name="base_scan">
    <visual>
      <origin xyz="0 0 0" rpy="0 0 0"/>
      <geometry>
        <mesh filename="package://turtlebot3_description/meshes/sensors/lds.stl" scale="0.001 0.001 0.001"/>
      </geometry>
      <material name="dark"/>
    </visual>
    <collision>
      <origin xyz="0.015 0 -0.0065" rpy="0 0 0"/>
      <geometry>
        <cylinder length="0.0315" radius="0.055"/>
      </geometry>
    </collision>
    <inertial>
      <mass value="0.114" />
      <origin xyz="0 0 0" />
      <inertia ixx="0.001" ixy="0.0" ixz="0.0" iyy="0.001" iyz="0.0" izz="0.001" />
    </inertial>
  </link>

  <!-- Storage Box with Lid -->
  <joint name="storage_box_joint" type="fixed">
    <origin xyz="-0.08 0 0.14" rpy="0 0 0"/>
    <parent link="base_link"/>
    <child link="storage_box_link"/>
  </joint>

  <link name="storage_box_link">
    <visual>
      <origin xyz="0 0 0.025" rpy="0 0 0"/>
      <geometry>
        <box size="0.15 0.12 0.05"/>
      </geometry>
      <material name="brown">
        <color rgba="0.8 0.6 0.4 1.0"/>
      </material>
    </visual>
    <collision>
      <origin xyz="0 0 0.025" rpy="0 0 0"/>
      <geometry>
        <box size="0.15 0.12 0.05"/>
      </geometry>
    </collision>
    <inertial>
      <origin xyz="0 0 0.025" rpy="0 0 0"/>
      <mass value="0.2"/>
      <inertia ixx="0.0004" ixy="0" ixz="0" iyy="0.0005" iyz="0" izz="0.0006"/>
    </inertial>
  </link>

  <!-- Hinged Lid -->
  <joint name="lid_joint" type="revolute">
    <origin xyz="-0.075 0 0.05" rpy="0 0 0"/>
    <parent link="storage_box_link"/>
    <child link="lid_link"/>
    <axis xyz="0 1 0"/>
    <limit lower="0" upper="1.5708" effort="10" velocity="1.0"/>
    <dynamics damping="0.1" friction="0.01"/>
  </joint>

  <link name="lid_link">
    <visual>
      <origin xyz="0.075 0 0.0125" rpy="0 0 0"/>
      <geometry>
        <box size="0.15 0.12 0.025"/>
      </geometry>
      <material name="dark_brown">
        <color rgba="0.6 0.4 0.2 1.0"/>
      </material>
    </visual>
    <collision>
      <origin xyz="0.075 0 0.0125" rpy="0 0 0"/>
      <geometry>
        <box size="0.15 0.12 0.025"/>
      </geometry>
    </collision>
    <inertial>
      <origin xyz="0.075 0 0.0125" rpy="0 0 0"/>
      <mass value="0.1"/>
      <inertia ixx="0.0002" ixy="0" ixz="0" iyy="0.0003" iyz="0" izz="0.0003"/>
    </inertial>
  </link>

  <!-- Gazebo materials -->
  <gazebo reference="storage_box_link">
    <material>Gazebo/Wood</material>
  </gazebo>
  
  <gazebo reference="lid_link">
    <material>Gazebo/WoodPallet</material>
  </gazebo>

  <!-- Gazebo differential drive plugin -->
  <gazebo>
    <plugin name="turtlebot3_diff_drive" filename="libgazebo_ros_diff_drive.so">
      <ros>
        <namespace>/</namespace>
        <remapping>cmd_vel:=cmd_vel</remapping>
        <remapping>odom:=odom</remapping>
      </ros>
      <update_rate>30</update_rate>
      <left_joint>wheel_left_joint</left_joint>
      <right_joint>wheel_right_joint</right_joint>
      <wheel_separation>0.287</wheel_separation>
      <wheel_diameter>0.066</wheel_diameter>
      <max_wheel_torque>20</max_wheel_torque>
      <max_wheel_acceleration>1.0</max_wheel_acceleration>
      <command_topic>cmd_vel</command_topic>
      <publish_odom>true</publish_odom>
      <publish_odom_tf>true</publish_odom_tf>
      <publish_wheel_tf>false</publish_wheel_tf>
      <odometry_topic>odom</odometry_topic>
      <odometry_frame>odom</odometry_frame>
      <robot_base_frame>base_footprint</robot_base_frame>
    </plugin>
  </gazebo>

  <!-- ROS2 Control for lid -->
  <ros2_control name="GazeboSystem" type="system">
    <hardware>
      <plugin>gazebo_ros2_control/GazeboSystem</plugin>
    </hardware>
    <joint name="lid_joint">
      <command_interface name="position">
        <param name="min">0</param>
        <param name="max">1.5708</param>
      </command_interface>
      <state_interface name="position"/>
    </joint>
  </ros2_control>

  <gazebo>
    <plugin filename="libgazebo_ros2_control.so" name="gazebo_ros2_control">
      <parameters>$(find lid_control)/config/lid_controllers.yaml</parameters>
    </plugin>
  </gazebo>

</robot>
