<?xml version="1.0"?>
<robot name="storage_lid" xmlns:xacro="http://ros.org/wiki/xacro">

  <xacro:include filename="$(find robot_description)/urdf/lid/lid.gazebo"/>

  <xacro:macro name="storage_lid" params="parent *joint_origin">
    
    <!-- Storage Box Base -->
    <joint name="storage_box_joint" type="fixed">
      <xacro:insert_block name="joint_origin"/>
      <parent link="${parent}"/>
      <child link="storage_box_link"/>
    </joint>

    <link name="storage_box_link">
      <visual>
        <origin xyz="0 0 0.025" rpy="0 0 0"/>
        <geometry>
          <box size="0.15 0.12 0.05"/>
        </geometry>
        <material name="box_material">
          <color rgba="0.8 0.6 0.4 1.0"/>
        </material>
      </visual>
      <collision>
        <origin xyz="0 0 0.025" rpy="0 0 0"/>
        <geometry>
          <box size="0.15 0.12 0.05"/>
        </geometry>
      </collision>
      <inertial>
        <origin xyz="0 0 0.025" rpy="0 0 0"/>
        <mass value="0.2"/>
        <inertia ixx="0.0004" ixy="0" ixz="0" iyy="0.0005" iyz="0" izz="0.0006"/>
      </inertial>
    </link>

    <!-- Hinged Lid -->
    <joint name="lid_hinge_joint" type="revolute">
      <origin xyz="-0.075 0 0.05" rpy="0 0 0"/>
      <parent link="storage_box_link"/>
      <child link="lid_link"/>
      <axis xyz="0 1 0"/>
      <limit lower="0" upper="1.5708" effort="10" velocity="1.0"/>
      <dynamics damping="0.1" friction="0.01"/>
    </joint>

    <link name="lid_link">
      <visual>
        <origin xyz="0.075 0 0.0125" rpy="0 0 0"/>
        <geometry>
          <box size="0.15 0.12 0.025"/>
        </geometry>
        <material name="lid_material">
          <color rgba="0.6 0.4 0.2 1.0"/>
        </material>
      </visual>
      <collision>
        <origin xyz="0.075 0 0.0125" rpy="0 0 0"/>
        <geometry>
          <box size="0.15 0.12 0.025"/>
        </geometry>
      </collision>
      <inertial>
        <origin xyz="0.075 0 0.0125" rpy="0 0 0"/>
        <mass value="0.1"/>
        <inertia ixx="0.0002" ixy="0" ixz="0" iyy="0.0003" iyz="0" izz="0.0003"/>
      </inertial>
    </link>

  </xacro:macro>

</robot>
